Workbook
Name MJR: #REF!
Name Period: #REF!

Sheet Summary
A1: PROJECT ANALYSIS SHEET
A3: Project Number:
A4: Customer: | E4: Programme Dates
A5: Project Name: | E5: Contract | F5: Actual
A6: Date of Review: | D6: Start
A7: Reporting Period: | D7: Finish
A8: PM:
A9: Project % Complete (as at period end):
B11: Current Period | C11: =B7 -> 0 | F11: Previous Period | G11: Movement in Period
A12: Final Forecast Costs (from Analysis) | B12: =B7 -> 0 | E12: CTC / Contingency | F12: =B7-30 -> -30 | H12: Reason for movement
C13: Actual | D13: Vos
A14: Labour | B14: =C14+E14 -> 0 | C14: =Analysis!$E$188 -> 0 | D14: =Analysis!$F$188 -> 0 | E14: =Analysis!$G$188 -> 0 | G14: =B14-F14 -> 0
A15: Materials | B15: =C15+E15 -> 0 | C15: =Analysis!$E$189 -> 0 | D15: =Analysis!$F$189 -> 0 | E15: =Analysis!$G$189 -> 0 | G15: =B15-F15 -> 0
A16: Sub Con | B16: =C16+E16 -> 0 | C16: =Analysis!$E$190 -> 0 | D16: =Analysis!$F$190 -> 0 | E16: =Analysis!$G$190 -> 0 | G16: =B16-F16 -> 0
A17: Prelims | B17: =C17+E17 -> 0 | C17: =Analysis!$E$191 -> 0 | D17: =Analysis!$F$191 -> 0 | E17: =Analysis!$G$191 -> 0 | G17: =B17-F17 -> 0
A18: Staff | B18: =C18+E18 -> 0 | C18: =Analysis!$E$192 -> 0 | D18: =Analysis!$F$192 -> 0 | E18: =Analysis!$G$192 -> 0 | G18: =B18-F18 -> 0
B19: =SUM(B14:B18) -> 0 | C19: =SUM(C14:C18) -> 0 | D19: =SUM(D14:D18) -> 0 | E19: =SUM(E14:E18) -> 0 | F19: =SUM(F14:F18) -> 0 | G19: =B19-F19 -> 0
A22: Total Cost | B22: =B12 -> 0 | F22: =F12 -> -30 | G22: Movement in Period | H22: Notes on significant movements
A24: Total Actual Costs Incurred | G24: =B24-F24 -> 0
A25: Outstanding Purchase Orders | G25: =B25-F25 -> 0
A26: Costs To Complete (From Analysis) | B26: =Analysis!$G$194 -> 0 | G26: =B26-F26 -> 0
B27: =SUM(B24:B26) -> 0 | F27: =SUM(F24:F26) -> 0 | G27: Total Actual Costs Incurred
A29: Check vs Forecast | B29: =B19-B27 -> 0
A31: Sales & Margin | B31: =B22 -> 0 | F31: =F12 -> -30 | G31: Movement in Period | H31: Notes on significant movements
A33: Order Value | B33: =Analysis!CR54 -> 0 | G33: =B33-F33 -> 0
A34: Variations | B34: =SUM(Analysis!CT133:CV133) -> 0 | F34: 0 | G34: =B34-F34 -> 0
A35: Contra-charges | B35: 0 | F35: 0 | G35: =B35-F35 -> 0
A36: MCD (where applicable) | B36: 0 | F36: 0 | G36: =B36-F36 -> 0
A37: Total Order Value | B37: =SUM(B33:B36) -> 0 | F37: =SUM(F33:F36) -> 0 | G37: =B37-F37 -> 0
A38: Final Profit | B38: =B37-B19 -> 0 | F38: =F37-F19 -> 0 | G38: =B38-F38 -> 0
A39: Gross Margin % | B39: =SUM(B38/B37) -> #DIV/0! | F39: =SUM(F38/F37) -> #DIV/0! | G39: =B39-F39 -> #DIV/0!
B42: Dates | F42: £ | G42: % of forecast | H42: Comments
A43: Latest Cumulative Application (Gross) | F43: 25 | G43: =F43/B37 -> #DIV/0!
A44: Latest Cumulative Certification (Gross) | F44: 20 | G44: =F44/B37 -> #DIV/0!
A45: Previous Cumulative Application (Gross) | F45: 15 | G45: =F45/B37 -> #DIV/0!
A46: Previous Cumulative Certification (Gross) | F46: 10 | G46: =F46/B37 -> #DIV/0!
B47: Applied in Period | F47: =F43-F45 -> 10 | G47: =G43-G45 -> #DIV/0!
B48: Certified in Period | F48: =F44-F46 -> 10 | G48: =G44-G46 -> #DIV/0!
F49: Current App v Progress | G49: =G43-B9 -> #DIV/0!
F50: Current Cert v Progress | G50: =G44-B9 -> #DIV/0!
...

Sheet Analysis
A1: PROJECT ANALYSIS SHEET
A3: PROJECT:
A5: PROJECT N°:
AY6: Subby 1 | BA6: Subby 2 | BI6: Subby 3 | BJ6: Subby 4 | BL6: Subby 5 | BO6: Subby 6 | BR6: Subby 7 | BX6: Subby 8
A7: Tender Labour Rate: | L7: Materials | AY7: Sub - Contract | BZ7: Prelims | CQ7: Summary
J8: VO Labour Rate:
A9: Description of Work | J9: Hours | K9: Labour Total | L9: Chilled water Pipework & Fittings | M9: Strip out | N9: Compressed air pipework & materials | O9: H&CWS pipework & materials | P9: Condensate Recovery Unit | Q9: Steam & Condensate DB&B's, Trapsets, PRV's etc. | R9: Steam & Condensate pipework and fittings | S9: Jacket Heater Water MPHW? | T9: Valves | U9: Pressurisation (APS) | V9: Gauges,Cocks and Syphons | W9: Air Separator | X9: Hose Reel System | Y9: Dosing Pot | Z9: Buffer Vessel and Ancillaries | AA9: above ground drainage | AB9: Sanitaryware | AC9: Stainless Steel Troughs | AD9: Emergency Shower | AE9: Gantries, Builderswork Fabric & Flooring | AF9: Air socks | AG9: RO Water Treatment Inc install and Comm | AH9: Unit Heaters | AI9: Hot Purified Water (Valves not in Cost & Sell) | AJ9: Radiators | AK9: Grilles | AL9: Attenuators | AM9: AHUs | AN9: AHU Commission | AO9: Fans | AP9: Penthouse Louvres | AQ9: Motorised damper and controls | AR9: Canopies | AS9: cooling coils | AT9: Smoke Dampers & Actuators | AU9: Labelling | AV9: Gas Boosters | AW9: Room Heat recovery Ventilation units | AX9: Expansion | AY9: Ductwork Installation | AZ9: Stainless Ductwork | BA9: Thermal Insulation | BB9: Trace Heating | BC9: Cranage & Plant Positioning | BD9: Temporary Power & Lighting | BE9: Strip Out | BF9: De-gassing & Strip-out A/C units & Condensors place into storage | BG9: Wi/Fi | BH9: Compressed Air inc Survey | BI9: BMS / EMS | BJ9: BMS Wiring | BK9: Control Panel & Wiring | BL9: Test, Commission, Handover | BM9: Water treatment and chlorination | BN9: Allowance for Glycol | BO9: Gantries, Builderswork Fabric & Flooring | BP9: Surveys Isolations | BQ9: Smoke Dampers & Actuators | BR9: Sprinklers | BS9: Site Cleaning | BT9: above ground drainage | BU9: Staff Training | BV9: Pipework (Surepipe) Labour | BW9: Pipework Materials | BX9: Pipework Management/Access/Site set up | BY9: Electrical & Fire alarm Installation | BZ9: Site Meeting attendance PM | CA9: Quantity Surveyor | CB9: Access Equipment | CC9: Asbestos Survey | CD9: Health and Safety Mark Mallen | CE9: Non Working Site Manager | CF9: SM assistant | CG9: consumables/First aid/PPE | CH9: Craneage / Lift & Shift | CI9: Handover Documents,O+M and Drawings | CJ9: Staff Training | CK9: Site set up cabins/fencing/Signage | CL9: Tools & Equipment | CM9: Waste Handling/Skips | CN9: Design Costs | CO9: PM Costs | CP9: Coordination Costs | CQ9: Total Cost | CR9: Order Value | CT9: Budget | CU9: Submitted | CV9: Agreed
A11: TENDER COSTS
A12: 1
A13: 2
A14: 3
A15: 4
A16: 5
A17: 6
A18: 7
A19: 8
A20: 9
A21: 10
A22: 11
A23: 12
... A51: 40
J54: =SUM(J12:J53) -> 0 | K54: =SUM(K12:K53) -> 0 | L54: =SUM(L12:L53) -> 0 | M54: =SUM(M12:M53) -> 0 | N54: =SUM(N12:N53) -> 0 | O54: =SUM(O12:O53) -> 0 | P54: =SUM(P12:P53) -> 0 | Q54: =SUM(Q12:Q53) -> 0 | ... AU54: =SUM(AU12:AU53) -> 0 | AW54: =SUM(AW12:AW53) -> 0 | AX54: =SUM(AX12:AX53) -> 0 | AY54: =SUM(AY12:AY53) -> 0 | AZ54: =SUM(AZ12:AZ53) -> 0 | BA54: =SUM(BA12:BA53) -> 0 | BB54: =SUM(BB12:BB53) -> 0 | BC54: =SUM(BC12:BC53) -> 0 | BD54: =SUM(BD12:BD53) -> 0 | ... CR54: =SUM(CR12:CR53) -> 0
CQ55: Profit | CR55: =CR54-CQ54 -> 0
CQ56: % Profit | CR56: =IF(CR55=0,0,CR55/CR54) -> 0
A57: Actual Costs | J57: Actual Costs | L57: Actual Order Values | BZ57: Actual Costs
A58: =A12 -> 1 | I58: =I12 -> 0 | K58: =SUM(J58*$K$7) -> 0
A59: =A13 -> 2 | I59: =I13 -> 0 | K59: =SUM(J59*$K$7) -> 0
A60: =A14 -> 3 | I60: =I14 -> 0 | K60: =SUM(J60*$K$7) -> 0
A61: =A15 -> 4 | I61: =I15 -> 0 | K61: =SUM(J61*$K$7) -> 0
A62: =A16 -> 5 | I62: =I16 -> 0 | K62: =SUM(J62*$K$7) -> 0
A63: =A17 -> 6 | I63: =I17 -> 0 | K63: =SUM(J63*$K$7) -> 0
A64: =A18 -> 7 | I64: =I18 -> 0 | K64: =SUM(J64*$K$7) -> 0
A65: =A19 -> 8 | I65: =I19 -> 0 | K65: =SUM(J65*$K$7) -> 0
A66: =A20 -> 9 | I66: =I20 -> 0 | K66: =SUM(J66*$K$7) -> 0
A67: =A21 -> 10 | I67: =I21 -> 0 | K67: =SUM(J67*$K$7) -> 0
A68: =A22 -> 11 | I68: =I22 -> 0 | J68: 0 | K68: =SUM(J68*$K$7) -> 0
A69: =A23 -> 12 | I69: =I23 -> 0 | K69: =SUM(J69*$K$7) -> 0
A70: =A24 -> 13 | I70: =I24 -> 0 | K70: =SUM(J70*$K$7) -> 0
A71: =A25 -> 14 | I71: =I25 -> 0 | K71: =SUM(J71*$K$7) -> 0
A72: =A26 -> 15 | I72: =I26 -> 0 | K72: =SUM(J72*$K$7) -> 0
...

Sheet Prelims
A1: Cabins and Stores | D1: 53 weeks | E1: 6841
A2: Additional 8 weeks @£120 per week | E2: 960 | G2: Contract Period
G3: Deffered start | P3: Additional Prelims
A5: On Site Management costs
G6: 4 | H6: 4 | I6: 5 | J6: 4 | K6: 4 | L6: 5 | M6: 4 | N6: 5 | O6: 4 | P6: 4 | Q6: 3 | R6: 3 | S6: 4 | T6: 5 | U6: 4
F7: 45292 | G7: 45323 | H7: 45352 | I7: 45383 | J7: 45413 | K7: 45444 | L7: 45474 | M7: 45505 | N7: 45536 | O7: 45566 | P7: 45597 | Q7: 45627 | R7: 45658 | S7: 45689 | T7: 45717 | U7: 45748 | V7: Totals
D8: Site PM | E8: Sam | N8: =300*5*N6 -> 7500 | O8: =300*5*O6 -> 6000 | P8: =300*5*P6 -> 6000 | Q8: =300*5*Q6 -> 4500 | R8: =300*5*R6 -> 4500 | S8: =300*5*S6 -> 6000 | T8: =300*5*T6 -> 7500 | V8: =SUM(F8:U8) -> 42000
E9: Accom & Travel | N9: 1250 | O9: 1250 | P9: 1250 | Q9: 1250 | R9: 1250 | S9: 1250 | T9: 1250 | V9: =SUM(F9:T9) -> 8750
V10: =SUM(V8:V9) -> 50750
E12: Matthew | F12: (salary, expenses, hotel) | N12: =150*5*4.33 -> 3247.5 | O12: =150*5*4.33 -> 3247.5 | P12: =150*5*4.33 -> 3247.5 | Q12: =150*5*4.33 -> 3247.5 | R12: =150*5*4.33 -> 3247.5 | V12: =SUM(F12:T12) -> 16237.5
K15: Craig on Hols - 2 weeks
A16: PM | D16: PM | E16: Craig | N16: =400*5*N6 -> 10000 | O16: =400*5*O6 -> 8000 | P16: =400*5*P6 -> 8000 | Q16: =400*5*Q6 -> 6000 | R16: =400*5*R6 -> 6000 | S16: 6000 | T16: 6000 | V16: =SUM(F16:T16) -> 50000
A17: Travel | N17: =126*4.33 -> 545.58 | O17: =126*4.33 -> 545.58 | P17: =126*4.33 -> 545.58 | Q17: =126*4.33 -> 545.58 | R17: =126*4.33 -> 545.58 | S17: =126*4.33 -> 545.58 | T17: =126*4.33 -> 545.58 | V17: =SUM(F17:T17) -> 3819.06
A18: Acc | V18: =SUM(F18:S18) -> 0
V19: =SUM(F19:S19) -> 0
V20: =SUM(V15:V19) -> 53819.06

Sheet NOTES
