Workbook

Sheet VO Summary - Issue
A1: Variation Confirmation of Costs
A2: Project: | B2: Project X | H2: Project No:
A3: Client: | B3: Client X | H3: VCC No:
A5: To: | B5: Client X | F5: From: | G5: Project Manager X
B6: Street X
B7: Area X
A10: Copy to: | B10: Everyone | F10: Someone
A11: Copy to: | B11: Everyone else | F11: Someone else
A13: We advise you herewith of the variation costs associated with the work described below:
A14: Changes to first floor amenities area
A20: Instruction Reference:
A21: Client PM email 01/09/24 | H21: Make Up | I21: Add | J21: Omit
A22: Drawing Ref - 987654 Rev 2 | G22: 1 | H22: Staff | I22: ='Preliminaries Cost Sheet'!$I$37 -> 0 | J22: 0
A23: Programme ref Prog 01 - August 2024
G24: 2 | H24: Labour | I24: ='Variation Cost Sheet'!$N$61 -> 0 | J24: ='Variation Cost Sheet'!$Q$61 -> 0
A26: This variation advice is:- | G26: 3 | H26: Materials | I26: ='Variation Cost Sheet'!$N$52 -> 0 | J26: ='Variation Cost Sheet'!$Q$52 -> 0
B28: Budget Cost | G28: 4 | H28: Sub Contract | I28: ='Variation Cost Sheet'!$N$56 -> 0 | J28: ='Variation Cost Sheet'!$Q$56 -> 0
B29: Firm Cost
G30: 5 | H30: Design | I30: ='Preliminaries Cost Sheet'!$I$42 -> 0 | J30: 0
A32: Substantiating details in support of costs are:- | G32: 6 | H32: Prelims | I32: ='Preliminaries Cost Sheet'!$I$46 -> 0 | J32: 0
B34: Attached | G34: 7
B35: Will Follow
G36: 8
A38: Programme implications:-
B40: No | H40: Total Omit / Add: | I40: =SUM(I22:I39) -> 0 | J40: =SUM(J22:J39) -> 0
B41: Yes - See below comments:
H42: Total Variation: | J42: =J40+I40 -> 0
A43: Comments Here. 2 weeks Delay to progamme due to addittional instructed works.
A48: We await your written response before we proceed | G48: Variation valid until:
A50: SIGNED: | G50: DATE:
B53: IP 02-04-30 Version 2

Sheet VO Breakdown - Issue
A1: Variation Breakdown
A2: No. | B2: UoM | C2: Description | D2: ADD | E2: OMIT | F2: Total
C4: ='Variation Cost Sheet'!$E$11 -> LABOUR / MATERIALS / SUB-CONTRACTORS
A6: ='Variation Cost Sheet'!E14 -> 0 | B6: ='Variation Cost Sheet'!F14 -> 0 | C6: ='Variation Cost Sheet'!$G$14 -> 0 | D6: ='Variation Cost Sheet'!$N14 -> 0 | E6: ='Variation Cost Sheet'!$Q$14 -> 0 | F6: =SUM(D6:E6) -> 0
F7: =SUM(D7:E7) -> 0
F8: =SUM(D8:E8) -> 0
F9: =SUM(D9:E9) -> 0
A10: ='Variation Cost Sheet'!$E18 -> 0 | B10: ='Variation Cost Sheet'!F18 -> 0 | C10: ='Variation Cost Sheet'!$G18 -> 0 | D10: ='Variation Cost Sheet'!$N18 -> 0 | E10: ='Variation Cost Sheet'!$Q18 -> 0 | F10: =SUM(D10:E10) -> 0
A11: ='Variation Cost Sheet'!$E19 -> 0 | B11: ='Variation Cost Sheet'!F19 -> 0 | C11: ='Variation Cost Sheet'!$G19 -> 0 | D11: ='Variation Cost Sheet'!$N19 -> 0 | E11: ='Variation Cost Sheet'!$Q19 -> 0 | F11: =SUM(D11:E11) -> 0
A12: ='Variation Cost Sheet'!$E20 -> 0 | B12: ='Variation Cost Sheet'!F20 -> 0 | C12: ='Variation Cost Sheet'!$G20 -> 0 | D12: ='Variation Cost Sheet'!$N20 -> 0 | E12: ='Variation Cost Sheet'!$Q20 -> 0 | F12: =SUM(D12:E12) -> 0
A13: ='Variation Cost Sheet'!$E21 -> 0 | B13: ='Variation Cost Sheet'!F21 -> 0 | C13: ='Variation Cost Sheet'!$G21 -> 0 | D13: ='Variation Cost Sheet'!$N21 -> 0 | E13: ='Variation Cost Sheet'!$Q21 -> 0 | F13: =SUM(D13:E13) -> 0
A14: ='Variation Cost Sheet'!$E22 -> 0 | B14: ='Variation Cost Sheet'!F22 -> 0 | C14: ='Variation Cost Sheet'!$G22 -> 0 | D14: ='Variation Cost Sheet'!$N22 -> 0 | E14: ='Variation Cost Sheet'!$Q22 -> 0 | F14: =SUM(D14:E14) -> 0
A15: ='Variation Cost Sheet'!$E23 -> 0 | B15: ='Variation Cost Sheet'!F23 -> 0 | C15: ='Variation Cost Sheet'!$G23 -> 0 | D15: ='Variation Cost Sheet'!$N23 -> 0 | E15: ='Variation Cost Sheet'!$Q23 -> 0 | F15: =SUM(D15:E15) -> 0
A16: ='Variation Cost Sheet'!$E24 -> 0 | B16: ='Variation Cost Sheet'!F24 -> 0 | C16: ='Variation Cost Sheet'!$G24 -> 0 | D16: ='Variation Cost Sheet'!$N24 -> 0 | E16: ='Variation Cost Sheet'!$Q24 -> 0 | F16: =SUM(D16:E16) -> 0
A17: ='Variation Cost Sheet'!$E25 -> 0 | B17: ='Variation Cost Sheet'!F25 -> 0 | C17: ='Variation Cost Sheet'!$G25 -> 0 | D17: ='Variation Cost Sheet'!$N25 -> 0 | E17: ='Variation Cost Sheet'!$Q25 -> 0 | F17: =SUM(D17:E17) -> 0
A18: ='Variation Cost Sheet'!$E26 -> 0 | B18: ='Variation Cost Sheet'!F26 -> 0 | C18: ='Variation Cost Sheet'!$G26 -> 0 | D18: ='Variation Cost Sheet'!$N26 -> 0 | E18: ='Variation Cost Sheet'!$Q26 -> 0 | F18: =SUM(D18:E18) -> 0
A19: ='Variation Cost Sheet'!$E27 -> 0 | B19: ='Variation Cost Sheet'!F27 -> 0 | C19: ='Variation Cost Sheet'!$G27 -> 0 | D19: ='Variation Cost Sheet'!$N27 -> 0 | E19: ='Variation Cost Sheet'!$Q27 -> 0 | F19: =SUM(D19:E19) -> 0
A20: ='Variation Cost Sheet'!$E28 -> 0 | B20: ='Variation Cost Sheet'!F28 -> 0 | C20: ='Variation Cost Sheet'!$G28 -> 0 | D20: ='Variation Cost Sheet'!$N28 -> 0 | E20: ='Variation Cost Sheet'!$Q28 -> 0 | F20: =SUM(D20:E20) -> 0
A21: ='Variation Cost Sheet'!$E29 -> 0 | B21: ='Variation Cost Sheet'!F29 -> 0 | C21: ='Variation Cost Sheet'!$G29 -> 0 | D21: ='Variation Cost Sheet'!$N29 -> 0 | E21: ='Variation Cost Sheet'!$Q29 -> 0 | F21: =SUM(D21:E21) -> 0
... A39: ='Variation Cost Sheet'!$E47 -> 0 | B39: ='Variation Cost Sheet'!F47 -> 0 | C39: ='Variation Cost Sheet'!$G47 -> 0 | D39: ='Variation Cost Sheet'!$N47 -> 0 | E39: ='Variation Cost Sheet'!$Q47 -> 0 | F39: =SUM(D39:E39) -> 0
C40: TOTALS | D40: =SUM(D3:D39) -> 0 | E40: =SUM(E3:E39) -> 0 | F40: =SUM(F3:F39) -> 0
C43: ='Preliminaries Cost Sheet'!$E$9 -> STAFF | F43: =SUM(D43:E43) -> 0
C44: ='Preliminaries Cost Sheet'!$F11 -> Project Manager | F44: =SUM(D44:E44) -> 0
C45: ='Preliminaries Cost Sheet'!$F12 -> Director | F45: =SUM(D45:E45) -> 0
C46: ='Preliminaries Cost Sheet'!$F13 -> Site Foreman | F46: =SUM(D46:E46) -> 0
C47: ='Preliminaries Cost Sheet'!$F14 -> Site Labourer | F47: =SUM(D47:E47) -> 0
C48: ='Preliminaries Cost Sheet'!$F15 -> Quantity Surveyor | F48: =SUM(D48:E48) -> 0
C49: ='Preliminaries Cost Sheet'!$F16 -> Health & Safety Manager | F49: =SUM(D49:E49) -> 0
C50: ='Preliminaries Cost Sheet'!$F17 -> Site Manager | F50: =SUM(D50:E50) -> 0
C52: {='Preliminaries Cost Sheet'!$E$19:$G$19} -> DESIGN | D52: 0 | E52: 0
C53: ='Preliminaries Cost Sheet'!$F21 -> Design Engineer | F53: =SUM(D53:E53) -> 0
C54: ='Preliminaries Cost Sheet'!$F22 -> CAD Design | F54: =SUM(D54:E54) -> 0
C55: ='Preliminaries Cost Sheet'!$F23 -> Test | F55: =SUM(D55:E55) -> 0
C57: {='Preliminaries Cost Sheet'!$E$25:$G$25} -> PRELIMS | D57: 0 | E57: 0
C58: ='Preliminaries Cost Sheet'!$D27 -> Lodging | F58: =SUM(D58:E58) -> 0
C59: ='Preliminaries Cost Sheet'!$D28 -> Mileage | D59: ='Preliminaries Cost Sheet'!$I28 -> 0 | F59: =SUM(D59:E59) -> 0
C60: ='Preliminaries Cost Sheet'!$D29 -> Parking | D60: ='Preliminaries Cost Sheet'!$I29 -> 0 | F60: =SUM(D60:E60) -> 0
C61: ='Preliminaries Cost Sheet'!$D30 -> Access Equipment | F61: =SUM(D61:E61) -> 0
C62: ='Preliminaries Cost Sheet'!$D31 -> Tools & Equipment | D62: ='Preliminaries Cost Sheet'!$I31 -> 0 | F62: =SUM(D62:E62) -> 0
C63: ='Preliminaries Cost Sheet'!$D32 -> Training | D63: ='Preliminaries Cost Sheet'!$I32 -> 0 | F63: =SUM(D63:E63) -> 0
...

Sheet Variation Cost Sheet
B2: Variation No. | G2: ='VO Summary - Issue'!$I$3 -> 0
C4: PM | E4: ='VO Summary - Issue'!$G$5 -> Project Manager X | I4: Labour Rate | N4: 45 | Q4: 50
C5: Date | E5: ='VO Summary - Issue'!$H$50 -> 0 | I5: Labour Profit % | N5: 20 | Q5: 20
C6: Project Name | E6: ='VO Summary - Issue'!$B$2 -> Project X | I6: Material Profit % | N6: 20 | Q6: 20
C7: Project No | E7: ='VO Summary - Issue'!$I$2 -> 0 | I7: Sub-Contractor Profit % | N7: 20 | Q7: 20
I8: MCD % | N8: 5 | Q8: 0
C11: LABOUR | E11: LABOUR / MATERIALS / SUB-CONTRACTORS | M11: TOTALS | P11: TOTALS
C12: Total Hours | H12: ADD | J12: OMIT | M12: ADD | P12: OMIT
C13: ADD | D13: OMIT | E13: No. | F13: UoM | G13: Description | H13: Mat Cost | I13: Sub Cost | J13: Mat Cost | K13: Sub Cost | M13: Sub-Total | N13: Total | P13: Sub-Total | Q13: Total
M14: =SUM(H14*E14)+(C14*$N$4)+(I14*E14) -> 0 | N14: =(SUM(H14*E14/(1-$N$6/100))+(I14*E14/(1-$N$7/100))+(C14*$N$4/(1-$N$5/100)))*N$8%+(SUM(H14*E14/(1-$N$6/100))+(I14*E14/(1-$N$7/100))+(C14*$N$4/(1-$N$5/100))) -> 0 | P14: =SUM(-J14*E14)+(-D14*$Q$4)+(-K14*E14) -> 0 | Q14: =(SUM(-J14*E14/(1-$Q$6/100))-(K14*E14/(1-$Q$7/100))+(-D14*$Q$4/(1-$Q$5/100)))*Q$8%+SUM(-J14*E14/(1-$Q$6/100))+(-K14*E14/(1-$Q$7/100))+(-D14*$Q$4/(1-$Q$5/100)) -> 0
F15: Hours | G15: Labour | M15: =SUM(H15*E15)+(C15*$N$4)+(I15*E15) -> 0 | N15: =(SUM(H15*E15/(1-$N$6/100))+(I15*E15/(1-$N$7/100))+(C15*$N$4/(1-$N$5/100)))*N$8%+(SUM(H15*E15/(1-$N$6/100))+(I15*E15/(1-$N$7/100))+(C15*$N$4/(1-$N$5/100))) -> 0 | P15: =SUM(-J15*E15)+(-D15*$Q$4)+(-K15*E15) -> 0 | Q15: =(SUM(-J15*E15/(1-$Q$6/100))-(K15*E15/(1-$Q$7/100))+(-D15*$Q$4/(1-$Q$5/100)))*Q$8%+SUM(-J15*E15/(1-$Q$6/100))+(-K15*E15/(1-$Q$7/100))+(-D15*$Q$4/(1-$Q$5/100)) -> 0
F16: M | G16: Pipework | M16: =SUM(H16*E16)+(C16*$N$4)+(I16*E16) -> 0 | N16: =(SUM(H16*E16/(1-$N$6/100))+(I16*E16/(1-$N$7/100))+(C16*$N$4/(1-$N$5/100)))*N$8%+(SUM(H16*E16/(1-$N$6/100))+(I16*E16/(1-$N$7/100))+(C16*$N$4/(1-$N$5/100))) -> 0 | P16: =SUM(-J16*E16)+(-D16*$Q$4)+(-K16*E16) -> 0 | Q16: =(SUM(-J16*E16/(1-$Q$6/100))-(K16*E16/(1-$Q$7/100))+(-D16*$Q$4/(1-$Q$5/100)))*Q$8%+SUM(-J16*E16/(1-$Q$6/100))+(-K16*E16/(1-$Q$7/100))+(-D16*$Q$4/(1-$Q$5/100)) -> 0
F17: M | G17: Insulation | M17: =SUM(H17*E17)+(C17*$N$4)+(I17*E17) -> 0 | N17: =(SUM(H17*E17/(1-$N$6/100))+(I17*E17/(1-$N$7/100))+(C17*$N$4/(1-$N$5/100)))*N$8%+(SUM(H17*E17/(1-$N$6/100))+(I17*E17/(1-$N$7/100))+(C17*$N$4/(1-$N$5/100))) -> 0 | P17: =SUM(-J17*E17)+(-D17*$Q$4)+(-K17*E17) -> 0 | Q17: =(SUM(-J17*E17/(1-$Q$6/100))-(K17*E17/(1-$Q$7/100))+(-D17*$Q$4/(1-$Q$5/100)))*Q$8%+SUM(-J17*E17/(1-$Q$6/100))+(-K17*E17/(1-$Q$7/100))+(-D17*$Q$4/(1-$Q$5/100)) -> 0
M18: =SUM(H18*E18)+(C18*$N$4)+(I18*E18) -> 0 | N18: =(SUM(H18*E18/(1-$N$6/100))+(I18*E18/(1-$N$7/100))+(C18*$N$4/(1-$N$5/100)))*N$8%+(SUM(H18*E18/(1-$N$6/100))+(I18*E18/(1-$N$7/100))+(C18*$N$4/(1-$N$5/100))) -> 0 | P18: =SUM(-J18*E18)+(-D18*$Q$4)+(-K18*E18) -> 0 | Q18: =(SUM(-J18*E18/(1-$Q$6/100))-(K18*E18/(1-$Q$7/100))+(-D18*$Q$4/(1-$Q$5/100)))*Q$8%+SUM(-J18*E18/(1-$Q$6/100))+(-K18*E18/(1-$Q$7/100))+(-D18*$Q$4/(1-$Q$5/100)) -> 0
M19: =SUM(H19*E19)+(C19*$N$4)+(I19*E19) -> 0 | N19: =(SUM(H19*E19/(1-$N$6/100))+(I19*E19/(1-$N$7/100))+(C19*$N$4/(1-$N$5/100)))*N$8%+(SUM(H19*E19/(1-$N$6/100))+(I19*E19/(1-$N$7/100))+(C19*$N$4/(1-$N$5/100))) -> 0 | P19: =SUM(-J19*E19)+(-D19*$Q$4)+(-K19*E19) -> 0 | Q19: =(SUM(-J19*E19/(1-$Q$6/100))-(K19*E19/(1-$Q$7/100))+(-D19*$Q$4/(1-$Q$5/100)))*Q$8%+SUM(-J19*E19/(1-$Q$6/100))+(-K19*E19/(1-$Q$7/100))+(-D19*$Q$4/(1-$Q$5/100)) -> 0
M20: =SUM(H20*E20)+(C20*$N$4)+(I20*E20) -> 0 | N20: =(SUM(H20*E20/(1-$N$6/100))+(I20*E20/(1-$N$7/100))+(C20*$N$4/(1-$N$5/100)))*N$8%+(SUM(H20*E20/(1-$N$6/100))+(I20*E20/(1-$N$7/100))+(C20*$N$4/(1-$N$5/100))) -> 0 | P20: =SUM(-J20*E20)+(-D20*$Q$4)+(-K20*E20) -> 0 | Q20: =(SUM(-J20*E20/(1-$Q$6/100))-(K20*E20/(1-$Q$7/100))+(-D20*$Q$4/(1-$Q$5/100)))*Q$8%+SUM(-J20*E20/(1-$Q$6/100))+(-K20*E20/(1-$Q$7/100))+(-D20*$Q$4/(1-$Q$5/100)) -> 0
M21: =SUM(H21*E21)+(C21*$N$4)+(I21*E21) -> 0 | N21: =(SUM(H21*E21/(1-$N$6/100))+(I21*E21/(1-$N$7/100))+(C21*$N$4/(1-$N$5/100)))*N$8%+(SUM(H21*E21/(1-$N$6/100))+(I21*E21/(1-$N$7/100))+(C21*$N$4/(1-$N$5/100))) -> 0 | P21: =SUM(-J21*E21)+(-D21*$Q$4)+(-K21*E21) -> 0 | Q21: =(SUM(-J21*E21/(1-$Q$6/100))-(K21*E21/(1-$Q$7/100))+(-D21*$Q$4/(1-$Q$5/100)))*Q$8%+SUM(-J21*E21/(1-$Q$6/100))+(-K21*E21/(1-$Q$7/100))+(-D21*$Q$4/(1-$Q$5/100)) -> 0
M22: =SUM(H22*E22)+(C22*$N$4)+(I22*E22) -> 0 | N22: =(SUM(H22*E22/(1-$N$6/100))+(I22*E22/(1-$N$7/100))+(C22*$N$4/(1-$N$5/100)))*N$8%+(SUM(H22*E22/(1-$N$6/100))+(I22*E22/(1-$N$7/100))+(C22*$N$4/(1-$N$5/100))) -> 0 | P22: =SUM(-J22*E22)+(-D22*$Q$4)+(-K22*E22) -> 0 | Q22: =(SUM(-J22*E22/(1-$Q$6/100))-(K22*E22/(1-$Q$7/100))+(-D22*$Q$4/(1-$Q$5/100)))*Q$8%+SUM(-J22*E22/(1-$Q$6/100))+(-K22*E22/(1-$Q$7/100))+(-D22*$Q$4/(1-$Q$5/100)) -> 0
M23: =SUM(H23*E23)+(C23*$N$4)+(I23*E23) -> 0 | N23: =(SUM(H23*E23/(1-$N$6/100))+(I23*E23/(1-$N$7/100))+(C23*$N$4/(1-$N$5/100)))*N$8%+(SUM(H23*E23/(1-$N$6/100))+(I23*E23/(1-$N$7/100))+(C23*$N$4/(1-$N$5/100))) -> 0 | P23: =SUM(-J23*E23)+(-D23*$Q$4)+(-K23*E23) -> 0 | Q23: =(SUM(-J23*E23/(1-$Q$6/100))-(K23*E23/(1-$Q$7/100))+(-D23*$Q$4/(1-$Q$5/100)))*Q$8%+SUM(-J23*E23/(1-$Q$6/100))+(-K23*E23/(1-$Q$7/100))+(-D23*$Q$4/(1-$Q$5/100)) -> 0
M24: =SUM(H24*E24)+(C24*$N$4)+(I24*E24) -> 0 | N24: =(SUM(H24*E24/(1-$N$6/100))+(I24*E24/(1-$N$7/100))+(C24*$N$4/(1-$N$5/100)))*N$8%+(SUM(H24*E24/(1-$N$6/100))+(I24*E24/(1-$N$7/100))+(C24*$N$4/(1-$N$5/100))) -> 0 | P24: =SUM(-J24*E24)+(-D24*$Q$4)+(-K24*E24) -> 0 | Q24: =(SUM(-J24*E24/(1-$Q$6/100))-(K24*E24/(1-$Q$7/100))+(-D24*$Q$4/(1-$Q$5/100)))*Q$8%+SUM(-J24*E24/(1-$Q$6/100))+(-K24*E24/(1-$Q$7/100))+(-D24*$Q$4/(1-$Q$5/100)) -> 0
M25: =SUM(H25*E25)+(C25*$N$4)+(I25*E25) -> 0 | N25: =(SUM(H25*E25/(1-$N$6/100))+(I25*E25/(1-$N$7/100))+(C25*$N$4/(1-$N$5/100)))*N$8%+(SUM(H25*E25/(1-$N$6/100))+(I25*E25/(1-$N$7/100))+(C25*$N$4/(1-$N$5/100))) -> 0 | P25: =SUM(-J25*E25)+(-D25*$Q$4)+(-K25*E25) -> 0 | Q25: =(SUM(-J25*E25/(1-$Q$6/100))-(K25*E25/(1-$Q$7/100))+(-D25*$Q$4/(1-$Q$5/100)))*Q$8%+SUM(-J25*E25/(1-$Q$6/100))+(-K25*E25/(1-$Q$7/100))+(-D25*$Q$4/(1-$Q$5/100)) -> 0
M26: =SUM(H26*E26)+(C26*$N$4)+(I26*E26) -> 0 | N26: =(SUM(H26*E26/(1-$N$6/100))+(I26*E26/(1-$N$7/100))+(C26*$N$4/(1-$N$5/100)))*N$8%+(SUM(H26*E26/(1-$N$6/100))+(I26*E26/(1-$N$7/100))+(C26*$N$4/(1-$N$5/100))) -> 0 | P26: =SUM(-J26*E26)+(-D26*$Q$4)+(-K26*E26) -> 0 | Q26: =(SUM(-J26*E26/(1-$Q$6/100))-(K26*E26/(1-$Q$7/100))+(-D26*$Q$4/(1-$Q$5/100)))*Q$8%+SUM(-J26*E26/(1-$Q$6/100))+(-K26*E26/(1-$Q$7/100))+(-D26*$Q$4/(1-$Q$5/100)) -> 0
M27: =SUM(H27*E27)+(C27*$N$4)+(I27*E27) -> 0 | N27: =(SUM(H27*E27/(1-$N$6/100))+(I27*E27/(1-$N$7/100))+(C27*$N$4/(1-$N$5/100)))*N$8%+(SUM(H27*E27/(1-$N$6/100))+(I27*E27/(1-$N$7/100))+(C27*$N$4/(1-$N$5/100))) -> 0 | P27: =SUM(-J27*E27)+(-D27*$Q$4)+(-K27*E27) -> 0 | Q27: =(SUM(-J27*E27/(1-$Q$6/100))-(K27*E27/(1-$Q$7/100))+(-D27*$Q$4/(1-$Q$5/100)))*Q$8%+SUM(-J27*E27/(1-$Q$6/100))+(-K27*E27/(1-$Q$7/100))+(-D27*$Q$4/(1-$Q$5/100)) -> 0
M28: =SUM(H28*E28)+(C28*$N$4)+(I28*E28) -> 0 | N28: =(SUM(H28*E28/(1-$N$6/100))+(I28*E28/(1-$N$7/100))+(C28*$N$4/(1-$N$5/100)))*N$8%+(SUM(H28*E28/(1-$N$6/100))+(I28*E28/(1-$N$7/100))+(C28*$N$4/(1-$N$5/100))) -> 0 | P28: =SUM(-J28*E28)+(-D28*$Q$4)+(-K28*E28) -> 0 | Q28: =(SUM(-J28*E28/(1-$Q$6/100))-(K28*E28/(1-$Q$7/100))+(-D28*$Q$4/(1-$Q$5/100)))*Q$8%+SUM(-J28*E28/(1-$Q$6/100))+(-K28*E28/(1-$Q$7/100))+(-D28*$Q$4/(1-$Q$5/100)) -> 0
M29: =SUM(H29*E29)+(C29*$N$4)+(I29*E29) -> 0 | N29: =(SUM(H29*E29/(1-$N$6/100))+(I29*E29/(1-$N$7/100))+(C29*$N$4/(1-$N$5/100)))*N$8%+(SUM(H29*E29/(1-$N$6/100))+(I29*E29/(1-$N$7/100))+(C29*$N$4/(1-$N$5/100))) -> 0 | P29: =SUM(-J29*E29)+(-D29*$Q$4)+(-K29*E29) -> 0 | Q29: =(SUM(-J29*E29/(1-$Q$6/100))-(K29*E29/(1-$Q$7/100))+(-D29*$Q$4/(1-$Q$5/100)))*Q$8%+SUM(-J29*E29/(1-$Q$6/100))+(-K29*E29/(1-$Q$7/100))+(-D29*$Q$4/(1-$Q$5/100)) -> 0
... M48: =SUM(H48*E48)+(C48*$N$4)+(I48*E48) -> 0 | N48: =(SUM(H48*E48/(1-$N$6/100))+(I48*E48/(1-$N$7/100))+(C48*$N$4/(1-$N$5/100)))*N$8%+(SUM(H48*E48/(1-$N$6/100))+(I48*E48/(1-$N$7/100))+(C48*$N$4/(1-$N$5/100))) -> 0 | P48: =SUM(-J48*E48)+(-D48*$Q$4)+(-K48*E48) -> 0 | Q48: =(SUM(-J48*E48/(1-$Q$6/100))-(K48*E48/(1-$Q$7/100))+(-D48*$Q$4/(1-$Q$5/100)))*Q$8%+SUM(-J48*E48/(1-$Q$6/100))+(-K48*E48/(1-$Q$7/100))+(-D48*$Q$4/(1-$Q$5/100)) -> 0
H50: NETT MATERIALS | N50: =SUM(H14*E14)+(H15*E15)+(H16*E16)+(H17*E17)+(E18*H18)+(E19*H19)+(E20*H20)+(E21*H21)+(E22*H22)+(E23*H23)+(E24*H24)+(E25*H25)+(E26*H26)+(E27*H27)+(E28*H28)+(E29*H29)+(E30*H30)+(E31*H31)+(E32*H32)+(E33*H33)+(E34*H34)+(E35*H35)+(E36*H36)+(E37*H37)+(E38*H38)+(E39*H39)+(E40*H40)+(E41*H41)+(E42*H42)+(E43*H43)+(E44*H44)+(E45*H45)+(E46*H46)+(E47*H47)+(E48*H48) -> 0 | Q50: =SUM(-J14*E14)+(-J15*E15)+(-J16*E16)+(-J17*E17)+(E18*-J18)+(E19*-J19)+(E20*-J20)+(E21*-J21)+(E22*-J22)+(E23*-J23)+(E24*-J24)+(E25*-J25)+(E26*-J26)+(E27*-J27)+(E28*-J28)+(E29*-J29)+(E30*-J30)+(E31*-J31)+(E32*-J32)+(E33*-J33)+(E34*-J34)+(E35*-J35)+(E36*-J36)+(E37*-J37)+(E38*-J38)+(E39*-J39)+(E40*-J40)+(E41*-J41)+(E42*-J42)+(E43*-J43)+(E44*-J44)+(E45*-J45)+(E46*-J46)+(E47*-J47)+(E48*-J48) -> 0
H51: PROFIT £ | N51: =N52-N50 -> 0 | Q51: =Q52-Q50 -> 0
H52: TOTAL MATERIALS | N52: =SUM(N50/(1-N6/100))*N8%+SUM(N50/(1-N6/100)) -> 0 | Q52: =SUM(Q50/(1-Q6/100))*Q8%+SUM(Q50/(1-Q6/100)) -> 0
H54: NETT SUB-CONTRACTORS | N54: =SUM(I14*E14)+(I15*E15)+(I16*E16)+(I17*E17)+(I18*E18)+(I19*E19)+(I20*E20)+(I21*E21)+(I22*E22)+(I23*E23)+(I24*E24)+(I25*E25)+(I26*E26)+(I27*E27)+(I28*E28)+(I29*E29)+(I30*E30)+(I31*E31)+(I32*E32)+(I33*E33)+(I34*E34)+(I35*E35)+(I36*E36)+(I37*E37)+(I38*E38)+(I39*E39)+(I40*E40)+(I41*E41)+(I42*E42)+(I43*E43)+(I44*E44)+(I45*E45)+(I46*E46)+(I47*E47)+(I48*E48) -> 0 | Q54: =SUM(K14*-E14)+(K15*-E15)+(K16*-E16)+(K17*-E17)+(K18*-E18)+(K19*-E19)+(K20*-E20)+(K21*-E21)+(K22*-E22)+(K23*-E23)+(K24*-E24)+(K25*-E25)+(K26*-E26)+(K27*-E27)+(K28*-E28)+(K29*-E29)+(K30*-E30)+(K31*-E31)+(K32*-E32)+(K33*-E33)+(K34*-E34)+(K35*-E35)+(K36*-E36)+(K37*-E37)+(K38*-E38)+(K39*-E39)+(K40*-E40)+(K41*-E41)+(K42*-E42)+(K43*-E43)+(K44*-E44)+(K45*-E45)+(K46*-E46)+(K47*-E47)+(K48*-E48) -> 0
H55: PROFIT £ | N55: =N56-N54 -> 0 | Q55: =Q56-Q54 -> 0
H56: TOTAL SUB-CONTRACTORS | N56: =SUM(N54/(1-N7/100))*N8%+SUM(N54/(1-N7/100)) -> 0 | Q56: =SUM(Q54/(1-Q7/100))*Q8%+SUM(Q54/(1-Q7/100)) -> 0
H58: TOTAL LABOUR HOURS | N58: =SUM(C14:C48) -> 0 | Q58: =-SUM(D14:D48) -> 0
H59: NETT LABOUR | N59: =N58*N4 -> 0 | Q59: =Q58*Q4 -> 0
M60: PROFIT £ | N60: =N61-N59 -> 0 | Q60: =Q61-Q59 -> 0
H61: TOTAL LABOUR | N61: =SUM(N59/(1-N5/100))*N8%+SUM(N59/(1-N5/100)) -> 0 | Q61: =SUM(Q59/(1-Q5/100))*Q8%+SUM(Q59/(1-Q5/100)) -> 0
H63: TOTAL | N63: =N52+N56+N61 -> 0 | Q63: =Q52+Q56+Q61 -> 0
H64: ALL COSTS SUBJECT TO VAT

Sheet Preliminaries Cost Sheet
B2: Variation No. | F2: ='VO Summary - Issue'!$I$3 -> 0
C4: Project Manager | D4: ='VO Summary - Issue'!$G$5 -> Project Manager X | G4: Staff Costs Profit % | I4: 20
C5: Date | D5: ='VO Summary - Issue'!$H$50 -> 0 | G5: Design Profit % | I5: 35
C6: Project Name | D6: ='VO Summary - Issue'!$B$2 -> Project X | G6: Prelims Profit % | I6: 20
C7: Project No | D7: ='VO Summary - Issue'!$I$2 -> 0
C9: HOURS | E9: STAFF | H9: TOTALS
C10: Total Hours | D10: Hours | E10: Quantity | F10: Description | G10: Rate | H10: Sub-Total | I10: Total
C11: =D11*E11 -> 0 | F11: Project Manager | H11: =SUM(C11*G11) -> 0 | I11: =SUM(H11/(1-$I$4/100))+SUM(H11/100*'Variation Cost Sheet'!N8) -> 0
C12: =D12*E12 -> 0 | F12: Director | H12: =SUM(C12*G12) -> 0 | I12: =SUM(H12/(1-$I$4/100))+SUM(H12/100*'Variation Cost Sheet'!N8) -> 0
C13: =D13*E13 -> 0 | F13: Site Foreman | H13: =SUM(C13*G13) -> 0 | I13: =SUM(H13/(1-$I$4/100))+SUM(H13/100*'Variation Cost Sheet'!N8) -> 0
C14: =D14*E14 -> 0 | F14: Site Labourer | H14: =SUM(C14*G14) -> 0 | I14: =SUM(H14/(1-$I$4/100))+SUM(H14/100*'Variation Cost Sheet'!N8) -> 0
C15: =D15*E15 -> 0 | F15: Quantity Surveyor | H15: =SUM(C15*G15) -> 0 | I15: =SUM(H15/(1-$I$4/100))+SUM(H15/100*'Variation Cost Sheet'!N8) -> 0
C16: =D16*E16 -> 0 | F16: Health & Safety Manager | H16: =SUM(C16*G16) -> 0 | I16: =SUM(H16/(1-$I$4/100))+SUM(H16/100*'Variation Cost Sheet'!N8) -> 0
C17: =D17*E17 -> 0 | F17: Site Manager | H17: =SUM(C17*G17) -> 0 | I17: =SUM(H17/(1-$I$4/100))+SUM(H17/100*'Variation Cost Sheet'!N8) -> 0
C19: HOURS | E19: DESIGN | H19: TOTALS
C20: Total Hours | D20: Hours | E20: Quantity | F20: Description | G20: Rate | H20: Sub-Total | I20: Total
C21: =D21*E21 -> 0 | F21: Design Engineer | H21: =SUM(C21*G21) -> 0 | I21: =SUM(H21/(1-$I$5/100))+SUM(H21/100*'Variation Cost Sheet'!N8) -> 0
C22: =D22*E22 -> 0 | F22: CAD Design | H22: =SUM(C22*G22) -> 0 | I22: =SUM(H22/(1-$I$5/100))+SUM(H22/100*'Variation Cost Sheet'!N8) -> 0
C23: =D23*E23 -> 0 | F23: Test | H23: =SUM(C23*G23) -> 0 | I23: =SUM(H23/(1-$I$5/100))+SUM(H23/100*'Variation Cost Sheet'!N8) -> 0
E25: PRELIMS | H25: TOTALS
C26: Quantity | D26: Description | G26: Rate | H26: Sub-Total | I26: Total
C27: 1 | D27: Lodging | H27: =SUM(C27*G27) -> 0 | I27: =SUM(H27/(1-$I$6/100))+SUM(H27/100*'Variation Cost Sheet'!N8) -> 0
C28: 0 | D28: Mileage | H28: =SUM(C28*G28) -> 0 | I28: =SUM(H28/(1-$I$6/100))+SUM(H28/100*'Variation Cost Sheet'!N8) -> 0
C29: 0 | D29: Parking | H29: =SUM(C29*G29) -> 0 | I29: =SUM(H29/(1-$I$6/100))+SUM(H29/100*'Variation Cost Sheet'!N8) -> 0
C30: 2 | D30: Access Equipment | H30: =SUM(C30*G30) -> 0 | I30: =SUM(H30/(1-$I$6/100))+SUM(H30/100*'Variation Cost Sheet'!N8) -> 0
C31: 0 | D31: Tools & Equipment | H31: =SUM(C31*G31) -> 0 | I31: =SUM(H31/(1-$I$6/100))+SUM(H31/100*'Variation Cost Sheet'!N8) -> 0
C32: 0 | D32: Training | H32: =SUM(C32*G32) -> 0 | I32: =SUM(H32/(1-$I$6/100))+SUM(H32/100*'Variation Cost Sheet'!N8) -> 0
G34: TOTAL STAFF HOURS | I34: =SUM(C11:C17) -> 0
G35: NETT STAFF COSTS | I35: =SUM(H11:H17) -> 0
G36: PROFIT £ | I36: =I37-I35 -> 0
G37: TOTAL STAFF COSTS | I37: =SUM(I11:I17) -> 0
G39: TOTAL DESIGN HOURS | I39: =SUM(C21:C23) -> 0
G40: NETT DESIGN COSTS | I40: =SUM(H21:H23) -> 0
G41: PROFIT £ | I41: =I42-I40 -> 0
G42: TOTAL DESIGN COSTS | I42: =SUM(I21:I23) -> 0
G44: NETT PRELIMS COSTS | I44: =SUM(H27:H32) -> 0
G45: PROFIT £ | I45: =I46-I44 -> 0
G46: TOTAL MISCELLANEOUS COSTS | I46: =SUM(I27:I32) -> 0
G48: TOTAL | I48: =I37+I46+I42 -> 0
G49: ALL COSTS SUBJECT TO VAT

Sheet Labour Calcs 2025
A3: 2025 Labour charging rates
A4: Labour
J5: Normal hours | K5: P1 Overtime | L5: P2 Overtime | M5: Weekend rate
C6: Nett Cost | D6: NI Contribution | E6: Nett Total | F6: Travel costs | G6: Vehicle costs | H6: Holiday/sickness costs | I6: Nett cost | J6: Rate | K6: Rate | L6: Rate | M6: 4 x P1 + 12 X P2
A8: Up to 50 miles 45min e/w
F9: (based 1 hour/standard 8 hr day)
A10: Site supervisor | C10: 24 | D10: =C10*0.14 -> 3.36 | E10: =C10+D10 -> 27.36 | F10: =E10/8 -> 3.42 | G10: 3.1 | H10: =SUM(E10*8*25)/(47*5*8) -> 2.9106383 | M10: =((K10*4)+(12*L10))/16 -> 0
A11: Fitter Welder | C11: 23 | D11: =C11*0.14 -> 3.22 | E11: =C11+D11 -> 26.22 | F11: =E11/8 -> 3.2775 | G11: 3.1 | H11: =SUM(E11*8*25)/(47*5*8) -> 2.7893617 | M11: =((K11*4)+(12*L11))/16 -> 0
A12: Fitter or plumber | C12: 23 | D12: =C12*0.14 -> 3.22 | E12: =C12+D12 -> 26.22 | F12: =E12/8 -> 3.2775 | G12: 3.1 | H12: =SUM(E12*8*25)/(47*5*8) -> 2.7893617 | M12: =((K12*4)+(12*L12))/16 -> 0
A13: Improver / mate | C13: 20 | D13: =C13*0.14 -> 2.8 | E13: =C13+D13 -> 22.8 | F13: =E13/8 -> 2.85 | G13: 3.1 | H13: =SUM(E13*8*25)/(47*5*8) -> 2.4255319 | M13: =((K13*4)+(12*L13))/16 -> 0
A14: Labourer | C14: 17 | D14: =C14*0.14 -> 2.38 | E14: =C14+D14 -> 19.38 | F14: =E14/8 -> 2.4225 | G14: 3.1 | H14: =SUM(E14*8*25)/(47*5*8) -> 2.0617021 | M14: =((K14*4)+(12*L14))/16 -> 0
A17: Out of town 4 hours e/w travel, £100 / night allowance for lodge and expenses
F18: (based on 10 hr day@lodge rate of £100/night plus 8 hr travel/week) | M18: 5x P1 + 15 X P2
A19: Site supervisor | C19: 24 | D19: =C19*0.14 -> 3.36 | E19: =C19+D19 -> 27.36 | F19: =(100*4)/50+(E19*8/50) -> 12.3776 | G19: 3.1 | H19: =SUM(E19*10*25)/(47*5*10) -> 2.9106383 | M19: =((K19*5)+(15*L19))/20 -> 0
A20: Fitter Welder | C20: 23 | D20: =C20*0.14 -> 3.22 | E20: =C20+D20 -> 26.22 | F20: =(100*4)/50+(E20*8/50) -> 12.1952 | G20: 3.1 | H20: =SUM(E20*10*25)/(47*5*10) -> 2.7893617 | M20: =((K20*5)+(15*L20))/20 -> 0
A21: Fitter or plumber | C21: 23 | D21: =C21*0.14 -> 3.22 | E21: =C21+D21 -> 26.22 | F21: =(100*4)/50+(E21*8/50) -> 12.1952 | G21: 3.1 | H21: =SUM(E21*10*25)/(47*5*10) -> 2.7893617 | M21: =((K21*5)+(15*L21))/20 -> 0
A22: Improver / mate | C22: 20 | D22: =C22*0.14 -> 2.8 | E22: =C22+D22 -> 22.8 | F22: =(100*4)/50+(E22*8/50) -> 11.648 | G22: 3.1 | H22: =SUM(E22*10*25)/(47*5*10) -> 2.4255319 | M22: =((K22*5)+(15*L22))/20 -> 0
A23: Labourer | C23: 17 | D23: =C23*0.14 -> 2.38 | E23: =C23+D23 -> 19.38 | F23: =(100*4)/50+(E23*8/50) -> 11.1008 | G23: 3.1 | H23: =SUM(E23*10*25)/(47*5*10) -> 2.0617021 | M23: =((K23*5)+(15*L23))/20 -> 0
